<?xml version="1.0" ?>
<!-- =================================================================================== -->
<!-- |    This document was autogenerated by xacro from puma560_robot.urdf.xacro       | -->
<!-- |    EDITING THIS FILE BY HAND IS NOT RECOMMENDED                                 | -->
<!-- =================================================================================== -->
<robot name="BRTIRUS2110A" xmlns:xacro="http://www.ros.org/wiki/xacro">
  <material name="blue">
    <color rgba="0 0 0.8 0.8"/>
  </material>
  <material name="red">
    <color rgba="0.8 0 0 0.8"/>
  </material>
  <material name="green">
    <color rgba="0 0.8 0 0.8"/>
  </material>
  <!-- DH Paramaters -->
  <link name="link1">
    <visual>
      <geometry>
        <mesh filename="package://BRTIRUS2110A_description/meshes/base_link.stl"/>
      </geometry>
      <origin
        xyz="0 0 0"
        rpy="1.57079632679 0 3.14159265"/>
        <!-- rpy="1.57079632679 0 0"/> -->
      <material name="green"/>
    </visual>
  </link>
  <link name="link2">
    <visual>
      <geometry>
        <mesh filename="package://BRTIRUS2110A_description/meshes/link1.stl"/>
      </geometry>
      <origin
        rpy="1.57079632679 0 0" 
        xyz="0 0 0.2596"/>
      <material name="red"/>
    </visual>
  </link>
  <joint name="j1" type="revolute">
    <parent link="link1"/>
    <child link="link2"/>
    <origin 
      rpy="0 0 0" 
      xyz="0 0 0"/>
    <axis xyz="0 1 0"/>
    <!-- This is descibed in child frame -->
    <limit effort="1000.0" lower="-3.14159265" upper="3.14159265" velocity="0"/>
  </joint>
  <link name="link3">
    <visual>
      <geometry>
        <mesh filename="package://BRTIRUS2110A_description/meshes/link2.stl"/>
      </geometry>
      <origin 
        xyz="0 0 0"
        rpy="1.57079632679 0 0" />
      <material name="blue"/>
    </visual>
  </link>
  <joint name="j2" type="revolute">
    <parent link="link2"/>
    <child link="link3"/>
    <origin 
      rpy="0 0 0" 
      xyz="0.170 -0.103 0.4946"/>
    <axis xyz="0 1 0"/>
    <!-- This is descibed in child frame -->
    <limit effort="1000.0" lower="-1.570796325" upper="1.570796325" velocity="0"/>
  </joint>
  <link name="link4">
    <visual>
      <geometry>
        <mesh filename="package://BRTIRUS2110A_description/meshes/link3.stl"/>
      </geometry>
      <origin 
        rpy="1.57079632679 0 -1.57079632679" 
        xyz="0 0 0"/>
      <material name="green"/>
    </visual>
  </link>
  <joint name="j3" type="revolute">
    <parent link="link3"/>
    <child link="link4"/>
    <origin 
      rpy="0 0 0" 
      xyz="0 0.103 0.730"/>
    <axis xyz="0 1 0"/>
    <!-- This is descibed in child frame -->
    <limit effort="1000.0" lower="-1.570796325" upper="1.570796325" velocity="0"/>
  </joint>
  <link name="link5">
    <visual>
      <geometry>
        <mesh filename="package://BRTIRUS2110A_description/meshes/link4.stl"/>
      </geometry>
      <origin 
        rpy="3.14159265 0 3.14159265"
        xyz="0 0 0"/>
      <material name="red"/>
    </visual>
  </link>
  <joint name="j4" type="revolute">
    <parent link="link4"/>
    <child link="link5"/>
    <origin 
      rpy="0 0 0"
      xyz="0.2805 0 0.1"/>
    <axis xyz="0 0 1"/>
    <limit effort="1000.0" lower="-1.570796325" upper="1.570796325" velocity="0"/>
  </joint>
  <link name="link6">
    <visual>
      <geometry>
        <mesh filename="package://BRTIRUS2110A_description/meshes/link5.stl"/>
      </geometry>
      <origin 
        rpy="0 1.57079632679 0"
        xyz="0 0 0"/>
      <material name="green"/>
    </visual>
  </link>
  <joint name="j5" type="revolute">
    <parent link="link5"/>
    <child link="link6"/>
    <origin 
      rpy="1.57079632679 0 0"
      xyz="0 0 0.198"/>
    <axis xyz="1 0 0"/>
    <limit effort="1000.0" lower="-1.570796325" upper="1.570796325" velocity="0"/>
  </joint>
  <link name="link7">
    <visual>
      <geometry>
        <mesh filename="package://BRTIRUS2110A_description/meshes/link6.stl"/>
      </geometry>
      <origin 
        rpy="0 0 0"
        xyz="0 0 0.0075"/>
      <material name="blue"/>
    </visual>
  </link>
  <joint name="j6" type="revolute">
    <parent link="link6"/>
    <child link="link7"/>
    <origin 
      rpy="1.57079632679 0 0"
      xyz="0 0.107 0"/>
    <axis xyz="0 0 1"/>
    <limit effort="1000.0" lower="-3.14159265359" upper="3.14159265359" velocity="0"/>
  </joint>
  <!-- <link name="link_gripper_body">
    <visual>
      <geometry>
        <mesh filename="package://BRTIRUS2110A_description/meshes/gripper_body.stl"/>
      </geometry>
      <origin 
        rpy="3.14159265359 0 0"
        xyz="0 0 0.206"/>
      <material name="blue"/>
    </visual>
  </link>
  <joint name="j7" type="fixed">
    <parent link="link7"/>
    <child link="link_gripper_body"/>
    <origin 
      rpy="0 0 0"
      xyz="0 0 -0.206"/>
  </joint>
  <link name="link_finger_u">
    <visual>
      <geometry>
        <mesh filename="package://BRTIRUS2110A_description/meshes/gripper_finger_u.stl"/>
      </geometry>
      <origin 
        rpy="3.14159265359 0 0"
        xyz="0 0 0.206"/>
      <material name="blue"/>
    </visual>
  </link>
  <joint name="j_gripper_finger_u" type="prismatic">
    <parent link="link_gripper_body"/>
    <child link="link_finger_u"/>
    <origin 
      rpy="0 0 0"
      xyz="0 0 0"/>
    <axis xyz="1 0 0"/>
    <limit effort="1000.0" lower="0" upper="0.03" velocity="0"/>
  </joint>
  <link name="link_finger_b">
    <visual>
      <geometry>
        <mesh filename="package://BRTIRUS2110A_description/meshes/gripper_finger_b.stl"/>
      </geometry>
      <origin 
        rpy="3.14159265359 0 0"
        xyz="0 0 0.206"/>
      <material name="blue"/>
    </visual>
  </link>
  <joint name="j_gripper_finger_b" type="prismatic">
    <parent link="link_gripper_body"/>
    <child link="link_finger_b"/>
    <origin 
      rpy="0 0 0"
      xyz="0 0 0"/>
    <axis xyz="-1 0 0"/>
    <limit effort="1000.0" lower="0" upper="0.03" velocity="0"/>
  </joint> -->
</robot>

